Traceback (most recent call last):
  File "c:\Users\IBRAHIM\Documents\ml-vet-journey\python\debugging\debugging01.py", line 3, in <module>
    raise Exception('This is the error message')
Exception: This is the error message
